Workbook

Sheet Japanese Results
A1: =IFERROR(__xludf.DUMMYFUNCTION("IMPORTRANGE(""https://docs.google.com/spreadsheets/d/1JRp1QFgRUeO6wUkbMBdCuSKPn0UMXY4laNYwSgpe9m4/edit?gid=0#gid=0"",""Sheet1!A:AB"")"),"Submission ID") -> Submission ID | B1: =IFERROR(__xludf.DUMMYFUNCTION("""COMPUTED_VALUE"""),"Respondent ID") -> Respondent ID | C1: =IFERROR(__xludf.DUMMYFUNCTION("""COMPUTED_VALUE"""),"Submitted at") -> Submitted at | D1: =IFERROR(__xludf.DUMMYFUNCTION("""COMPUTED_VALUE"""),"あなたの年齢層を教えてください。") -> あなたの年齢層を教えてください。 | E1: =IFERROR(__xludf.DUMMYFUNCTION("""COMPUTED_VALUE"""),"ご自身が最も当てはまると感じる性別を教えてください。") -> ご自身が最も当てはまると感じる性別を教えてください。 | F1: =IFERROR(__xludf.DUMMYFUNCTION("""COMPUTED_VALUE"""),"世帯年収（税引き前）を教えてください。") -> 世帯年収（税引き前）を教えてください。 | G1: =IFERROR(__xludf.DUMMYFUNCTION("""COMPUTED_VALUE"""),"主にお住まいの地域はどこですか。") -> 主にお住まいの地域はどこですか。 | H1: =IFERROR(__xludf.DUMMYFUNCTION("""COMPUTED_VALUE"""),"どのくらいの頻度でコーヒーを飲みますか。") -> どのくらいの頻度でコーヒーを飲みますか。 | I1: =IFERROR(__xludf.DUMMYFUNCTION("""COMPUTED_VALUE"""),"普段よく飲むコーヒーの種類は何ですか。") -> 普段よく飲むコーヒーの種類は何ですか。 | J1: =IFERROR(__xludf.DUMMYFUNCTION("""COMPUTED_VALUE"""),"Untitled short answer field") -> Untitled short answer field | K1: =IFERROR(__xludf.DUMMYFUNCTION("""COMPUTED_VALUE"""),"どのくらいの頻度で抹茶を飲みますか。") -> どのくらいの頻度で抹茶を飲みますか。 | L1: =IFERROR(__xludf.DUMMYFUNCTION("""COMPUTED_VALUE"""),"普段よく飲む抹茶の種類は何ですか。") -> 普段よく飲む抹茶の種類は何ですか。 | M1: =IFERROR(__xludf.DUMMYFUNCTION("""COMPUTED_VALUE"""),"Untitled short answer field") -> Untitled short answer field | N1: =IFERROR(__xludf.DUMMYFUNCTION("""COMPUTED_VALUE"""),"コーヒーと抹茶のどちらを選ぶか決める際、特に影響する要因は何ですか。（最大2つまで）") -> コーヒーと抹茶のどちらを選ぶか決める際、特に影響する要因は何ですか。（最大2つまで） | O1: =IFERROR(__xludf.DUMMYFUNCTION("""COMPUTED_VALUE"""),"Untitled short answer field") -> Untitled short answer field | P1: =IFERROR(__xludf.DUMMYFUNCTION("""COMPUTED_VALUE"""),"これらの飲み物をどのようにして飲むことが多いですか。（該当するものすべて）") -> これらの飲み物をどのようにして飲むことが多いですか。（該当するものすべて） | Q1: =IFERROR(__xludf.DUMMYFUNCTION("""COMPUTED_VALUE"""),"Untitled short answer field") -> Untitled short answer field | R1: =IFERROR(__xludf.DUMMYFUNCTION("""COMPUTED_VALUE"""),"どのくらいの頻度でカフェに行きますか。") -> どのくらいの頻度でカフェに行きますか。 | S1: =IFERROR(__xludf.DUMMYFUNCTION("""COMPUTED_VALUE"""),"カフェに行く主な理由は何ですか。") -> カフェに行く主な理由は何ですか。 | T1: =IFERROR(__xludf.DUMMYFUNCTION("""COMPUTED_VALUE"""),"Untitled short answer field") -> Untitled short answer field | U1: =IFERROR(__xludf.DUMMYFUNCTION("""COMPUTED_VALUE"""),"あなたにとって、良いカフェ体験とは何ですか。") -> あなたにとって、良いカフェ体験とは何ですか。 | V1: =IFERROR(__xludf.DUMMYFUNCTION("""COMPUTED_VALUE"""),"Untitled short answer field") -> Untitled short answer field | W1: =IFERROR(__xludf.DUMMYFUNCTION("""COMPUTED_VALUE"""),"コーヒーに特定の文化やイメージを結びつけますか。") -> コーヒーに特定の文化やイメージを結びつけますか。 | X1: =IFERROR(__xludf.DUMMYFUNCTION("""COMPUTED_VALUE"""),"抹茶に特定の文化やイメージを結びつけますか。") -> 抹茶に特定の文化やイメージを結びつけますか。 | Y1: =IFERROR(__xludf.DUMMYFUNCTION("""COMPUTED_VALUE"""),"以下の意見について、どの程度同意しますか。") -> 以下の意見について、どの程度同意しますか。 | Z1: =IFERROR(__xludf.DUMMYFUNCTION("""COMPUTED_VALUE"""),"Untitled linear scale field") -> Untitled linear scale field | AA1: =IFERROR(__xludf.DUMMYFUNCTION("""COMPUTED_VALUE"""),"Untitled linear scale field") -> Untitled linear scale field | AB1: =IFERROR(__xludf.DUMMYFUNCTION("""COMPUTED_VALUE"""),"コーヒー、抹茶、カフェ文化について、より詳しくお話を伺うための短いフォローアップ・インタビュー（15～20分・英語）に参加してもよいですか？※インタビューにご参加いただいた方には、謝礼として無料ドリンクまたはギフトカードを差し上げます。") -> コーヒー、抹茶、カフェ文化について、より詳しくお話を伺うための短いフォローアップ・インタビュー（15～20分・英語）に参加してもよいですか？※インタビューにご参加いただいた方には、謝礼として無料ドリンクまたはギフトカードを差し上げます。 | AK1: Submission ID | AL1: Respondent ID | AM1: Submitted at | AN1: What age group do you fall into? Translation | AO1: To which gender do you identify most with? Translation | AP1: What is your total household income before taxes? Translation | AQ1: What region of Japan do you primarily live in? Translation | AR1: How often do you drink coffee? Translation | AS1: What coffee beverage do you usually drink? | AT1: Untitled short answer field | AU1: How often do you drink matcha? | AV1: What matcha beverage do you usually drink? | AW1: Untitled short answer field | AX1: When choosing between coffee and matcha, what factors influence your choice most? (Select up to two) | AY1: Untitled short answer field | AZ1: How do you usually consume these drinks? (Select all that apply) | BA1: Untitled short answer field | BB1: How often do you visit cafés? | BC1: What is your main reason for visiting a café? | BD1: Untitled short answer field | BE1: In your opinion, what makes a good café experience? | BF1: Untitled short answer field | BG1: Do you associate coffee with any particular culture or image? | BH1: Do you associate matcha with any particular culture or image? | BI1: How strongly do you agree with the following statements: | BJ1: Untitled linear scale field | BK1: Untitled linear scale field | BL1: Would you be open to a short (15–20 minute) follow-up interview in English to discuss your thoughts about coffee, matcha, and café culture in more detail? Participants who take part in a follow-up interview will be offered a free drink/gift card as a thank-you for their time. | BM1: Please provide your email address so I can contact you:
A2: =IFERROR(__xludf.DUMMYFUNCTION("""COMPUTED_VALUE"""),"EkoA68o") -> EkoA68o | B2: =IFERROR(__xludf.DUMMYFUNCTION("""COMPUTED_VALUE"""),"LZp8NDy") -> LZp8NDy | C2: =IFERROR(__xludf.DUMMYFUNCTION("""COMPUTED_VALUE"""),46028.188055555554) -> 46028.188 | D2: =IFERROR(__xludf.DUMMYFUNCTION("""COMPUTED_VALUE"""),"18〜25歳") -> 18〜25歳 | E2: =IFERROR(__xludf.DUMMYFUNCTION("""COMPUTED_VALUE"""),"男性") -> 男性 | F2: =IFERROR(__xludf.DUMMYFUNCTION("""COMPUTED_VALUE"""),"1,200万円以上") -> 1,200万円以上 | G2: =IFERROR(__xludf.DUMMYFUNCTION("""COMPUTED_VALUE"""),"関東") -> 関東 | H2: =IFERROR(__xludf.DUMMYFUNCTION("""COMPUTED_VALUE"""),"まったく飲まない") -> まったく飲まない | K2: =IFERROR(__xludf.DUMMYFUNCTION("""COMPUTED_VALUE"""),"ほとんど飲まない") -> ほとんど飲まない | L2: =IFERROR(__xludf.DUMMYFUNCTION("""COMPUTED_VALUE"""),"薄茶") -> 薄茶 | N2: =IFERROR(__xludf.DUMMYFUNCTION("""COMPUTED_VALUE"""),"味・風味, 健康面のメリット") -> 味・風味, 健康面のメリット | P2: =IFERROR(__xludf.DUMMYFUNCTION("""COMPUTED_VALUE"""),"自動販売機, コンビニ（セブンイレブン、ローソンなど）") -> 自動販売機, コンビニ（セブンイレブン、ローソンなど） | R2: =IFERROR(__xludf.DUMMYFUNCTION("""COMPUTED_VALUE"""),"ほとんど行かない") -> ほとんど行かない | S2: =IFERROR(__xludf.DUMMYFUNCTION("""COMPUTED_VALUE"""),"友人と会うため") -> 友人と会うため | U2: =IFERROR(__xludf.DUMMYFUNCTION("""COMPUTED_VALUE"""),"飲み物の味・品質") -> 飲み物の味・品質 | W2: =IFERROR(__xludf.DUMMYFUNCTION("""COMPUTED_VALUE"""),"はい（西洋的）") -> はい（西洋的） | X2: =IFERROR(__xludf.DUMMYFUNCTION("""COMPUTED_VALUE"""),"はい（日本的）") -> はい（日本的） | Y2: =IFERROR(__xludf.DUMMYFUNCTION("""COMPUTED_VALUE"""),4.0) -> 4 | Z2: =IFERROR(__xludf.DUMMYFUNCTION("""COMPUTED_VALUE"""),6.0) -> 6 | AA2: =IFERROR(__xludf.DUMMYFUNCTION("""COMPUTED_VALUE"""),4.0) -> 4 | AB2: =IFERROR(__xludf.DUMMYFUNCTION("""COMPUTED_VALUE"""),"いいえ") -> いいえ | AK2: EkoA68o | AL2: LZp8NDy | AM2: 46028.188 | AN2: {=IF(D2:D1000="","",XLOOKUP(D2:D1000, 'Translation Key'!$A:$A, 'Translation Key'!$B:$B))} -> 18-25 | AO2: {=IF(E2:E1000="","",XLOOKUP(E2:E1000, 'Translation Key'!$A:$A, 'Translation Key'!$B:$B))} -> Male | AP2: {=IF(F2:F1000="","",XLOOKUP(F2:F1000, 'Translation Key'!$A:$A, 'Translation Key'!$B:$B))} -> ¥12,000,000 or more | AQ2: {=IF(G2:G1000="","",XLOOKUP(G2:G1000, 'Translation Key'!$A:$A, 'Translation Key'!$B:$B))} -> Kanto | AR2: {=IF(H2:H1000="","",XLOOKUP(H2:H1000, 'Translation Key'!$A:$A, 'Translation Key'!$B:$B))} -> Never | AS2: {=IF(I2:I1000="","",XLOOKUP(I2:I1000, 'Translation Key'!$A:$A, 'Translation Key'!$B:$B))} | AU2: {=IF(K2:K1000="","",XLOOKUP(K2:K1000, 'Translation Key'!$A:$A, 'Translation Key'!$B:$B))} -> Rarely | AV2: {=IF(L2:L1000="","",XLOOKUP(L2:L1000, 'Translation Key'!$A:$A, 'Translation Key'!$B:$B))} -> Usucha | AX2: =IFERROR(__xludf.DUMMYFUNCTION("ARRAYFORMULA(IF(N2:N1000="""","""", BYROW(N2:N1000, LAMBDA(cell, IF(cell="""","""", JOIN("", "", ARRAYFORMULA( IFERROR( XLOOKUP( TRIM(TRANSPOSE(SPLIT(cell,"",""))), 'Translation Key'!$A:$A, 'Translation Key'!$B:$B ), TRIM(TRANSPOSE(SPLIT(cell,"&""",""))) ) ) ) ) )) ))"),"Taste/Flavor, Health benefits") -> Taste/Flavor, Health benefits | AZ2: =IFERROR(__xludf.DUMMYFUNCTION("ARRAYFORMULA(IF(P2:P1000="""","""", BYROW(P2:P1000, LAMBDA(cell, IF(cell="""","""", JOIN("", "", ARRAYFORMULA( IFERROR( XLOOKUP( TRIM(TRANSPOSE(SPLIT(cell,"",""))), 'Translation Key'!$A:$A, 'Translation Key'!$B:$B ), TRIM(TRANSPOSE(SPLIT(cell,"&""",""))) ) ) ) ) )) ))"),"From vending machines, From convenience stores (7-Eleven, Lawson, etc.)") -> From vending machines, From convenience stores (7-Eleven, Lawson, etc.) | BB2: {=IF(R2:R1000="","",XLOOKUP(R2:R1000, 'Translation Key'!$A:$A, 'Translation Key'!$B:$B))} -> Rarely | BC2: {=IF(S2:S1000="","",XLOOKUP(S2:S1000, 'Translation Key'!$A:$A, 'Translation Key'!$B:$B))} -> To meet friends | BE2: {=IF(U2:U1000="","",XLOOKUP(U2:U1000, 'Translation Key'!$A:$A, 'Translation Key'!$B:$B))} -> Quality of drinks | BG2: {=IF(W2:W1000="","",XLOOKUP(W2:W1000, 'Translation Key'!$A:$A, 'Translation Key'!$B:$B))} -> Yes, Western | BH2: {=IF(X2:X1000="","",XLOOKUP(X2:X1000, 'Translation Key'!$A:$A, 'Translation Key'!$B:$B))} -> Yes, Japanese | BI2: {=IF(Y2:Y1000="","",XLOOKUP(Y2:Y1000, 'Translation Key'!$A:$A, 'Translation Key'!$B:$B))} -> 4 | BJ2: {=IF(Z2:Z1000="","",XLOOKUP(Z2:Z1000, 'Translation Key'!$A:$A, 'Translation Key'!$B:$B))} -> 6 | BK2: {=IF(AA2:AA1000="","",XLOOKUP(AA2:AA1000, 'Translation Key'!$A:$A, 'Translation Key'!$B:$B))} -> 4 | BL2: {=IF(AB2:AB1000="","",XLOOKUP(AB2:AB1000, 'Translation Key'!$A:$A, 'Translation Key'!$B:$B))} -> No
A3: =IFERROR(__xludf.DUMMYFUNCTION("""COMPUTED_VALUE"""),"J9Ey24r") -> J9Ey24r | B3: =IFERROR(__xludf.DUMMYFUNCTION("""COMPUTED_VALUE"""),"xXarWEd") -> xXarWEd | C3: =IFERROR(__xludf.DUMMYFUNCTION("""COMPUTED_VALUE"""),46029.96582175926) -> 46029.966 | D3: =IFERROR(__xludf.DUMMYFUNCTION("""COMPUTED_VALUE"""),"26〜35歳") -> 26〜35歳 | E3: =IFERROR(__xludf.DUMMYFUNCTION("""COMPUTED_VALUE"""),"女性") -> 女性 | F3: =IFERROR(__xludf.DUMMYFUNCTION("""COMPUTED_VALUE"""),"300万円未満") -> 300万円未満 | G3: =IFERROR(__xludf.DUMMYFUNCTION("""COMPUTED_VALUE"""),"関東") -> 関東 | H3: =IFERROR(__xludf.DUMMYFUNCTION("""COMPUTED_VALUE"""),"週に数回") -> 週に数回 | I3: =IFERROR(__xludf.DUMMYFUNCTION("""COMPUTED_VALUE"""),"ドリップコーヒー") -> ドリップコーヒー | K3: =IFERROR(__xludf.DUMMYFUNCTION("""COMPUTED_VALUE"""),"週に数回") -> 週に数回 | L3: =IFERROR(__xludf.DUMMYFUNCTION("""COMPUTED_VALUE"""),"薄茶") -> 薄茶 | N3: =IFERROR(__xludf.DUMMYFUNCTION("""COMPUTED_VALUE"""),"価格, 味・風味") -> 価格, 味・風味 | P3: =IFERROR(__xludf.DUMMYFUNCTION("""COMPUTED_VALUE"""),"自宅で") -> 自宅で | R3: =IFERROR(__xludf.DUMMYFUNCTION("""COMPUTED_VALUE"""),"週に数回") -> 週に数回 | S3: =IFERROR(__xludf.DUMMYFUNCTION("""COMPUTED_VALUE"""),"友人と会うため") -> 友人と会うため | U3: =IFERROR(__xludf.DUMMYFUNCTION("""COMPUTED_VALUE"""),"雰囲気・心地良さ") -> 雰囲気・心地良さ | W3: =IFERROR(__xludf.DUMMYFUNCTION("""COMPUTED_VALUE"""),"はい（西洋的）") -> はい（西洋的） | X3: =IFERROR(__xludf.DUMMYFUNCTION("""COMPUTED_VALUE"""),"はい（日本的）") -> はい（日本的） | Y3: =IFERROR(__xludf.DUMMYFUNCTION("""COMPUTED_VALUE"""),3.0) -> 3 | Z3: =IFERROR(__xludf.DUMMYFUNCTION("""COMPUTED_VALUE"""),6.0) -> 6 | AA3: =IFERROR(__xludf.DUMMYFUNCTION("""COMPUTED_VALUE"""),5.0) -> 5 | AB3: =IFERROR(__xludf.DUMMYFUNCTION("""COMPUTED_VALUE"""),"いいえ") -> いいえ | AK3: J9Ey24r | AL3: xXarWEd | AM3: 46029.966 | AN3: 26-35 | AO3: Female | AP3: Under ¥3,000,000 | AQ3: Kanto | AR3: Several times a week | AS3: Drip | AU3: Several times a week | AV3: Usucha | AX3: =IFERROR(__xludf.DUMMYFUNCTION("""COMPUTED_VALUE"""),"Price, Taste/Flavor") -> Price, Taste/Flavor | AZ3: =IFERROR(__xludf.DUMMYFUNCTION("""COMPUTED_VALUE"""),"At home") -> At home | BB3: Several times a week | BC3: To meet friends | BE3: Atmosphere | BG3: Yes, Western | BH3: Yes, Japanese | BI3: 3 | BJ3: 6 | BK3: 5 | BL3: No
A4: =IFERROR(__xludf.DUMMYFUNCTION("""COMPUTED_VALUE"""),"ODxRYQA") -> ODxRYQA | B4: =IFERROR(__xludf.DUMMYFUNCTION("""COMPUTED_VALUE"""),"Y5WP1Lv") -> Y5WP1Lv | C4: =IFERROR(__xludf.DUMMYFUNCTION("""COMPUTED_VALUE"""),46029.97939814815) -> 46029.979 | D4: =IFERROR(__xludf.DUMMYFUNCTION("""COMPUTED_VALUE"""),"18〜25歳") -> 18〜25歳 | E4: =IFERROR(__xludf.DUMMYFUNCTION("""COMPUTED_VALUE"""),"男性") -> 男性 | F4: =IFERROR(__xludf.DUMMYFUNCTION("""COMPUTED_VALUE"""),"600万円〜899万9,999円") -> 600万円〜899万9,999円 | G4: =IFERROR(__xludf.DUMMYFUNCTION("""COMPUTED_VALUE"""),"関東") -> 関東 | H4: =IFERROR(__xludf.DUMMYFUNCTION("""COMPUTED_VALUE"""),"毎日") -> 毎日 | I4: =IFERROR(__xludf.DUMMYFUNCTION("""COMPUTED_VALUE"""),"ドリップコーヒー") -> ドリップコーヒー | K4: =IFERROR(__xludf.DUMMYFUNCTION("""COMPUTED_VALUE"""),"毎日") -> 毎日 | L4: =IFERROR(__xludf.DUMMYFUNCTION("""COMPUTED_VALUE"""),"濃茶") -> 濃茶 | N4: =IFERROR(__xludf.DUMMYFUNCTION("""COMPUTED_VALUE"""),"味・風味, エナジー／カフェイン") -> 味・風味, エナジー／カフェイン | P4: =IFERROR(__xludf.DUMMYFUNCTION("""COMPUTED_VALUE"""),"カフェで, 自宅で") -> カフェで, 自宅で | R4: =IFERROR(__xludf.DUMMYFUNCTION("""COMPUTED_VALUE"""),"週に数回") -> 週に数回 | S4: =IFERROR(__xludf.DUMMYFUNCTION("""COMPUTED_VALUE"""),"新しい飲み物を試すため") -> 新しい飲み物を試すため | U4: =IFERROR(__xludf.DUMMYFUNCTION("""COMPUTED_VALUE"""),"飲み物の味・品質") -> 飲み物の味・品質 | W4: =IFERROR(__xludf.DUMMYFUNCTION("""COMPUTED_VALUE"""),"はい（グローバル）") -> はい（グローバル） | X4: =IFERROR(__xludf.DUMMYFUNCTION("""COMPUTED_VALUE"""),"はい（日本的）") -> はい（日本的） | Y4: =IFERROR(__xludf.DUMMYFUNCTION("""COMPUTED_VALUE"""),3.0) -> 3 | Z4: =IFERROR(__xludf.DUMMYFUNCTION("""COMPUTED_VALUE"""),4.0) -> 4 | AA4: =IFERROR(__xludf.DUMMYFUNCTION("""COMPUTED_VALUE"""),3.0) -> 3 | AB4: =IFERROR(__xludf.DUMMYFUNCTION("""COMPUTED_VALUE"""),"いいえ") -> いいえ | AK4: ODxRYQA | AL4: Y5WP1Lv | AM4: 46029.979 | AN4: 18-25 | AO4: Male | AP4: ¥6,000,000 – ¥8,999,999 | AQ4: Kanto | AR4: Daily | AS4: Drip | AU4: Daily | AV4: Koicha | AX4: =IFERROR(__xludf.DUMMYFUNCTION("""COMPUTED_VALUE"""),"Taste/Flavor, Energy boost/Caffeine") -> Taste/Flavor, Energy boost/Caffeine | AZ4: =IFERROR(__xludf.DUMMYFUNCTION("""COMPUTED_VALUE"""),"At cafés, At home") -> At cafés, At home | BB4: Several times a week | BC4: To try a new drink | BE4: Quality of drinks | BG4: Yes, Global | BH4: Yes, Japanese | BI4: 3 | BJ4: 4 | BK4: 3 | BL4: No
A5: =IFERROR(__xludf.DUMMYFUNCTION("""COMPUTED_VALUE"""),"Zjb0xWz") -> Zjb0xWz | B5: =IFERROR(__xludf.DUMMYFUNCTION("""COMPUTED_VALUE"""),"q4Aa8P9") -> q4Aa8P9 | C5: =IFERROR(__xludf.DUMMYFUNCTION("""COMPUTED_VALUE"""),46030.24071759259) -> 46030.241 | D5: =IFERROR(__xludf.DUMMYFUNCTION("""COMPUTED_VALUE"""),"36〜45歳") -> 36〜45歳 | E5: =IFERROR(__xludf.DUMMYFUNCTION("""COMPUTED_VALUE"""),"男性") -> 男性 | F5: =IFERROR(__xludf.DUMMYFUNCTION("""COMPUTED_VALUE"""),"回答しない") -> 回答しない | G5: =IFERROR(__xludf.DUMMYFUNCTION("""COMPUTED_VALUE"""),"関東") -> 関東 | H5: =IFERROR(__xludf.DUMMYFUNCTION("""COMPUTED_VALUE"""),"毎日") -> 毎日 | I5: =IFERROR(__xludf.DUMMYFUNCTION("""COMPUTED_VALUE"""),"プアオーバー（ハンドドリップ）") -> プアオーバー（ハンドドリップ） | K5: =IFERROR(__xludf.DUMMYFUNCTION("""COMPUTED_VALUE"""),"週に数回") -> 週に数回 | L5: =IFERROR(__xludf.DUMMYFUNCTION("""COMPUTED_VALUE"""),"薄茶") -> 薄茶 | N5: =IFERROR(__xludf.DUMMYFUNCTION("""COMPUTED_VALUE"""),"味・風味") -> 味・風味 | P5: =IFERROR(__xludf.DUMMYFUNCTION("""COMPUTED_VALUE"""),"カフェで") -> カフェで | R5: =IFERROR(__xludf.DUMMYFUNCTION("""COMPUTED_VALUE"""),"週に数回") -> 週に数回 | S5: =IFERROR(__xludf.DUMMYFUNCTION("""COMPUTED_VALUE"""),"その他：") -> その他： | T5: =IFERROR(__xludf.DUMMYFUNCTION("""COMPUTED_VALUE"""),"お店の人と会話をしたいため") -> お店の人と会話をしたいため | U5: =IFERROR(__xludf.DUMMYFUNCTION("""COMPUTED_VALUE"""),"その他：") -> その他： | V5: =IFERROR(__xludf.DUMMYFUNCTION("""COMPUTED_VALUE"""),"その時の利用目的による") -> その時の利用目的による | W5: =IFERROR(__xludf.DUMMYFUNCTION("""COMPUTED_VALUE"""),"はい（グローバル）") -> はい（グローバル） | X5: =IFERROR(__xludf.DUMMYFUNCTION("""COMPUTED_VALUE"""),"はい（グローバル）") -> はい（グローバル） | Y5: =IFERROR(__xludf.DUMMYFUNCTION("""COMPUTED_VALUE"""),7.0) -> 7 | Z5: =IFERROR(__xludf.DUMMYFUNCTION("""COMPUTED_VALUE"""),7.0) -> 7 | AA5: =IFERROR(__xludf.DUMMYFUNCTION("""COMPUTED_VALUE"""),7.0) -> 7 | AB5: =IFERROR(__xludf.DUMMYFUNCTION("""COMPUTED_VALUE"""),"いいえ") -> いいえ | AK5: Zjb0xWz | AL5: q4Aa8P9 | AM5: 46030.241 | AN5: 36-45 | AO5: Male | AP5: Prefer not to say | AQ5: Kanto | AR5: Daily | AS5: Pour Over | AU5: Several times a week | AV5: Usucha | AX5: =IFERROR(__xludf.DUMMYFUNCTION("""COMPUTED_VALUE"""),"Taste/Flavor") -> Taste/Flavor | AZ5: =IFERROR(__xludf.DUMMYFUNCTION("""COMPUTED_VALUE"""),"At cafés") -> At cafés | BB5: Several times a week | BC5: Other: | BD5: Because I want to talk with the staff. | BE5: Other: | BF5: It depends on the purpose at that time. | BG5: Yes, Global | BH5: Yes, Global | BI5: 7 | BJ5: 7 | BK5: 7 | BL5: No
A6: =IFERROR(__xludf.DUMMYFUNCTION("""COMPUTED_VALUE"""),"GxAKvz2") -> GxAKvz2 | B6: =IFERROR(__xludf.DUMMYFUNCTION("""COMPUTED_VALUE"""),"jaQQQKx") -> jaQQQKx | C6: =IFERROR(__xludf.DUMMYFUNCTION("""COMPUTED_VALUE"""),46031.24113425926) -> 46031.241 | D6: =IFERROR(__xludf.DUMMYFUNCTION("""COMPUTED_VALUE"""),"18〜25歳") -> 18〜25歳 | E6: =IFERROR(__xludf.DUMMYFUNCTION("""COMPUTED_VALUE"""),"女性") -> 女性 | F6: =IFERROR(__xludf.DUMMYFUNCTION("""COMPUTED_VALUE"""),"回答しない") -> 回答しない | G6: =IFERROR(__xludf.DUMMYFUNCTION("""COMPUTED_VALUE"""),"関東") -> 関東 | H6: =IFERROR(__xludf.DUMMYFUNCTION("""COMPUTED_VALUE"""),"毎日") -> 毎日 | I6: =IFERROR(__xludf.DUMMYFUNCTION("""COMPUTED_VALUE"""),"ドリップコーヒー") -> ドリップコーヒー | K6: =IFERROR(__xludf.DUMMYFUNCTION("""COMPUTED_VALUE"""),"週に数回") -> 週に数回 | L6: =IFERROR(__xludf.DUMMYFUNCTION("""COMPUTED_VALUE"""),"抹茶ラテ") -> 抹茶ラテ | N6: =IFERROR(__xludf.DUMMYFUNCTION("""COMPUTED_VALUE"""),"味・風味") -> 味・風味 | P6: =IFERROR(__xludf.DUMMYFUNCTION("""COMPUTED_VALUE"""),"自宅で") -> 自宅で | R6: =IFERROR(__xludf.DUMMYFUNCTION("""COMPUTED_VALUE"""),"月に数回") -> 月に数回 | S6: =IFERROR(__xludf.DUMMYFUNCTION("""COMPUTED_VALUE"""),"休憩・リラックスするため") -> 休憩・リラックスするため | U6: =IFERROR(__xludf.DUMMYFUNCTION("""COMPUTED_VALUE"""),"飲み物の味・品質") -> 飲み物の味・品質 | W6: =IFERROR(__xludf.DUMMYFUNCTION("""COMPUTED_VALUE"""),"はい（西洋的）") -> はい（西洋的） | X6: =IFERROR(__xludf.DUMMYFUNCTION("""COMPUTED_VALUE"""),"はい（日本的）") -> はい（日本的） | Y6: =IFERROR(__xludf.DUMMYFUNCTION("""COMPUTED_VALUE"""),7.0) -> 7 | Z6: =IFERROR(__xludf.DUMMYFUNCTION("""COMPUTED_VALUE"""),7.0) -> 7 | AA6: =IFERROR(__xludf.DUMMYFUNCTION("""COMPUTED_VALUE"""),4.0) -> 4 | AB6: =IFERROR(__xludf.DUMMYFUNCTION("""COMPUTED_VALUE"""),"いいえ") -> いいえ | AK6: GxAKvz2 | AL6: jaQQQKx | AM6: 46031.241 | AN6: 18-25 | AO6: Female | AP6: Prefer not to say | AQ6: Kanto | AR6: Daily | AS6: Drip | AU6: Several times a week | AV6: Matcha Latte | AX6: =IFERROR(__xludf.DUMMYFUNCTION("""COMPUTED_VALUE"""),"Taste/Flavor") -> Taste/Flavor | AZ6: =IFERROR(__xludf.DUMMYFUNCTION("""COMPUTED_VALUE"""),"At home") -> At home | BB6: A few times a month | BC6: To relax or take a break | BE6: Quality of drinks | BG6: Yes, Western | BH6: Yes, Japanese | BI6: 7 | BJ6: 7 | BK6: 4 | BL6: No
A7: =IFERROR(__xludf.DUMMYFUNCTION("""COMPUTED_VALUE"""),"814zo8o") -> 814zo8o | B7: =IFERROR(__xludf.DUMMYFUNCTION("""COMPUTED_VALUE"""),"EkQQQyN") -> EkQQQyN | C7: =IFERROR(__xludf.DUMMYFUNCTION("""COMPUTED_VALUE"""),46031.24151620371) -> 46031.242 | D7: =IFERROR(__xludf.DUMMYFUNCTION("""COMPUTED_VALUE"""),"18〜25歳") -> 18〜25歳 | E7: =IFERROR(__xludf.DUMMYFUNCTION("""COMPUTED_VALUE"""),"女性") -> 女性 | F7: =IFERROR(__xludf.DUMMYFUNCTION("""COMPUTED_VALUE"""),"300万円〜599万9,999円") -> 300万円〜599万9,999円 | G7: =IFERROR(__xludf.DUMMYFUNCTION("""COMPUTED_VALUE"""),"関東") -> 関東 | H7: =IFERROR(__xludf.DUMMYFUNCTION("""COMPUTED_VALUE"""),"週に数回") -> 週に数回 | I7: =IFERROR(__xludf.DUMMYFUNCTION("""COMPUTED_VALUE"""),"ラテ") -> ラテ | K7: =IFERROR(__xludf.DUMMYFUNCTION("""COMPUTED_VALUE"""),"週に数回") -> 週に数回 | L7: =IFERROR(__xludf.DUMMYFUNCTION("""COMPUTED_VALUE"""),"抹茶ラテ") -> 抹茶ラテ | N7: =IFERROR(__xludf.DUMMYFUNCTION("""COMPUTED_VALUE"""),"味・風味") -> 味・風味 | P7: =IFERROR(__xludf.DUMMYFUNCTION("""COMPUTED_VALUE"""),"カフェで, 自宅で") -> カフェで, 自宅で | R7: =IFERROR(__xludf.DUMMYFUNCTION("""COMPUTED_VALUE"""),"月に数回") -> 月に数回 | S7: =IFERROR(__xludf.DUMMYFUNCTION("""COMPUTED_VALUE"""),"新しい飲み物を試すため") -> 新しい飲み物を試すため | U7: =IFERROR(__xludf.DUMMYFUNCTION("""COMPUTED_VALUE"""),"雰囲気・心地良さ") -> 雰囲気・心地良さ | W7: =IFERROR(__xludf.DUMMYFUNCTION("""COMPUTED_VALUE"""),"わからない") -> わからない | X7: =IFERROR(__xludf.DUMMYFUNCTION("""COMPUTED_VALUE"""),"はい（日本的）") -> はい（日本的） | Y7: =IFERROR(__xludf.DUMMYFUNCTION("""COMPUTED_VALUE"""),4.0) -> 4 | Z7: =IFERROR(__xludf.DUMMYFUNCTION("""COMPUTED_VALUE"""),5.0) -> 5 | AA7: =IFERROR(__xludf.DUMMYFUNCTION("""COMPUTED_VALUE"""),6.0) -> 6 | AB7: =IFERROR(__xludf.DUMMYFUNCTION("""COMPUTED_VALUE"""),"いいえ") -> いいえ | AK7: 814zo8o | AL7: EkQQQyN | AM7: 46031.242 | AN7: 18-25 | AO7: Female | AP7: ¥3,000,000 – ¥5,999,999 | AQ7: Kanto | AR7: Several times a week | AS7: Latte | AU7: Several times a week | AV7: Matcha Latte | AX7: =IFERROR(__xludf.DUMMYFUNCTION("""COMPUTED_VALUE"""),"Taste/Flavor") -> Taste/Flavor | AZ7: =IFERROR(__xludf.DUMMYFUNCTION("""COMPUTED_VALUE"""),"At cafés, At home") -> At cafés, At home | BB7: A few times a month | BC7: To try a new drink | BE7: Atmosphere | BG7: Unsure | BH7: Yes, Japanese | BI7: 4 | BJ7: 5 | BK7: 6 | BL7: No
A8: =IFERROR(__xludf.DUMMYFUNCTION("""COMPUTED_VALUE"""),"dWex1GN") -> dWex1GN | B8: =IFERROR(__xludf.DUMMYFUNCTION("""COMPUTED_VALUE"""),"NpWVjdB") -> NpWVjdB | C8: =IFERROR(__xludf.DUMMYFUNCTION("""COMPUTED_VALUE"""),46031.95395833333) -> 46031.954 | D8: =IFERROR(__xludf.DUMMYFUNCTION("""COMPUTED_VALUE"""),"18〜25歳") -> 18〜25歳 | E8: =IFERROR(__xludf.DUMMYFUNCTION("""COMPUTED_VALUE"""),"女性") -> 女性 | F8: =IFERROR(__xludf.DUMMYFUNCTION("""COMPUTED_VALUE"""),"300万円〜599万9,999円") -> 300万円〜599万9,999円 | G8: =IFERROR(__xludf.DUMMYFUNCTION("""COMPUTED_VALUE"""),"関東") -> 関東 | H8: =IFERROR(__xludf.DUMMYFUNCTION("""COMPUTED_VALUE"""),"毎日") -> 毎日 | I8: =IFERROR(__xludf.DUMMYFUNCTION("""COMPUTED_VALUE"""),"プアオーバー（ハンドドリップ）") -> プアオーバー（ハンドドリップ） | K8: =IFERROR(__xludf.DUMMYFUNCTION("""COMPUTED_VALUE"""),"週に1回") -> 週に1回 | L8: =IFERROR(__xludf.DUMMYFUNCTION("""COMPUTED_VALUE"""),"抹茶ラテ") -> 抹茶ラテ | N8: =IFERROR(__xludf.DUMMYFUNCTION("""COMPUTED_VALUE"""),"味・風味") -> 味・風味 | P8: =IFERROR(__xludf.DUMMYFUNCTION("""COMPUTED_VALUE"""),"カフェで") -> カフェで | R8: =IFERROR(__xludf.DUMMYFUNCTION("""COMPUTED_VALUE"""),"週に数回") -> 週に数回 | S8: =IFERROR(__xludf.DUMMYFUNCTION("""COMPUTED_VALUE"""),"休憩・リラックスするため") -> 休憩・リラックスするため | U8: =IFERROR(__xludf.DUMMYFUNCTION("""COMPUTED_VALUE"""),"サービス") -> サービス | W8: =IFERROR(__xludf.DUMMYFUNCTION("""COMPUTED_VALUE"""),"はい（グローバル）") -> はい（グローバル） | X8: =IFERROR(__xludf.DUMMYFUNCTION("""COMPUTED_VALUE"""),"はい（日本的）") -> はい（日本的） | Y8: =IFERROR(__xludf.DUMMYFUNCTION("""COMPUTED_VALUE"""),4.0) -> 4 | Z8: =IFERROR(__xludf.DUMMYFUNCTION("""COMPUTED_VALUE"""),5.0) -> 5 | AA8: =IFERROR(__xludf.DUMMYFUNCTION("""COMPUTED_VALUE"""),5.0) -> 5 | AB8: =IFERROR(__xludf.DUMMYFUNCTION("""COMPUTED_VALUE"""),"はい") -> はい | AK8: dWex1GN | AL8: NpWVjdB | AM8: 46031.954 | AN8: 18-25 | AO8: Female | AP8: ¥3,000,000 – ¥5,999,999 | AQ8: Kanto | AR8: Daily | AS8: Pour Over | AU8: Once a week | AV8: Matcha Latte | AX8: =IFERROR(__xludf.DUMMYFUNCTION("""COMPUTED_VALUE"""),"Taste/Flavor") -> Taste/Flavor | AZ8: =IFERROR(__xludf.DUMMYFUNCTION("""COMPUTED_VALUE"""),"At cafés") -> At cafés | BB8: Several times a week | BC8: To relax or take a break | BE8: Service | BG8: Yes, Global | BH8: Yes, Japanese | BI8: 4 | BJ8: 5 | BK8: 5 | BL8: Yes
A9: =IFERROR(__xludf.DUMMYFUNCTION("""COMPUTED_VALUE"""),"rjM6VAp") -> rjM6VAp | B9: =IFERROR(__xludf.DUMMYFUNCTION("""COMPUTED_VALUE"""),"RG5L4bP") -> RG5L4bP | C9: =IFERROR(__xludf.DUMMYFUNCTION("""COMPUTED_VALUE"""),46032.076203703706) -> 46032.076 | D9: =IFERROR(__xludf.DUMMYFUNCTION("""COMPUTED_VALUE"""),"26〜35歳") -> 26〜35歳 | E9: =IFERROR(__xludf.DUMMYFUNCTION("""COMPUTED_VALUE"""),"女性") -> 女性 | F9: =IFERROR(__xludf.DUMMYFUNCTION("""COMPUTED_VALUE"""),"300万円未満") -> 300万円未満 | G9: =IFERROR(__xludf.DUMMYFUNCTION("""COMPUTED_VALUE"""),"関東") -> 関東 | H9: =IFERROR(__xludf.DUMMYFUNCTION("""COMPUTED_VALUE"""),"週に数回") -> 週に数回 | I9: =IFERROR(__xludf.DUMMYFUNCTION("""COMPUTED_VALUE"""),"ラテ") -> ラテ | K9: =IFERROR(__xludf.DUMMYFUNCTION("""COMPUTED_VALUE"""),"ほとんど飲まない") -> ほとんど飲まない | L9: =IFERROR(__xludf.DUMMYFUNCTION("""COMPUTED_VALUE"""),"濃茶") -> 濃茶 | N9: =IFERROR(__xludf.DUMMYFUNCTION("""COMPUTED_VALUE"""),"味・風味") -> 味・風味 | P9: =IFERROR(__xludf.DUMMYFUNCTION("""COMPUTED_VALUE"""),"カフェで, コンビニ（セブンイレブン、ローソンなど）") -> カフェで, コンビニ（セブンイレブン、ローソンなど） | R9: =IFERROR(__xludf.DUMMYFUNCTION("""COMPUTED_VALUE"""),"ほとんど行かない") -> ほとんど行かない | S9: =IFERROR(__xludf.DUMMYFUNCTION("""COMPUTED_VALUE"""),"勉強・仕事をするため") -> 勉強・仕事をするため | U9: =IFERROR(__xludf.DUMMYFUNCTION("""COMPUTED_VALUE"""),"雰囲気・心地良さ") -> 雰囲気・心地良さ | W9: =IFERROR(__xludf.DUMMYFUNCTION("""COMPUTED_VALUE"""),"はい（西洋的）") -> はい（西洋的） | X9: =IFERROR(__xludf.DUMMYFUNCTION("""COMPUTED_VALUE"""),"はい（日本的）") -> はい（日本的） | Y9: =IFERROR(__xludf.DUMMYFUNCTION("""COMPUTED_VALUE"""),7.0) -> 7 | Z9: =IFERROR(__xludf.DUMMYFUNCTION("""COMPUTED_VALUE"""),7.0) -> 7 | AA9: =IFERROR(__xludf.DUMMYFUNCTION("""COMPUTED_VALUE"""),5.0) -> 5 | AB9: =IFERROR(__xludf.DUMMYFUNCTION("""COMPUTED_VALUE"""),"いいえ") -> いいえ | AK9: rjM6VAp | AL9: RG5L4bP | AM9: 46032.076 | AN9: 26-35 | AO9: Female | AP9: Under ¥3,000,000 | AQ9: Kanto | AR9: Several times a week | AS9: Latte | AU9: Rarely | AV9: Koicha | AX9: =IFERROR(__xludf.DUMMYFUNCTION("""COMPUTED_VALUE"""),"Taste/Flavor") -> Taste/Flavor | AZ9: =IFERROR(__xludf.DUMMYFUNCTION("""COMPUTED_VALUE"""),"At cafés, From convenience stores (7-Eleven, Lawson, etc.)") -> At cafés, From convenience stores (7-Eleven, Lawson, etc.) | BB9: Rarely | BC9: To study/work | BE9: Atmosphere | BG9: Yes, Western | BH9: Yes, Japanese | BI9: 7 | BJ9: 7 | BK9: 5 | BL9: No
A10: =IFERROR(__xludf.DUMMYFUNCTION("""COMPUTED_VALUE"""),"obLABbe") -> obLABbe | B10: =IFERROR(__xludf.DUMMYFUNCTION("""COMPUTED_VALUE"""),"QK50l5k") -> QK50l5k | C10: =IFERROR(__xludf.DUMMYFUNCTION("""COMPUTED_VALUE"""),46032.25387731481) -> 46032.254 | D10: =IFERROR(__xludf.DUMMYFUNCTION("""COMPUTED_VALUE"""),"18〜25歳") -> 18〜25歳 | E10: =IFERROR(__xludf.DUMMYFUNCTION("""COMPUTED_VALUE"""),"女性") -> 女性 | F10: =IFERROR(__xludf.DUMMYFUNCTION("""COMPUTED_VALUE"""),"300万円未満") -> 300万円未満 | G10: =IFERROR(__xludf.DUMMYFUNCTION("""COMPUTED_VALUE"""),"中部") -> 中部 | H10: =IFERROR(__xludf.DUMMYFUNCTION("""COMPUTED_VALUE"""),"毎日") -> 毎日 | I10: =IFERROR(__xludf.DUMMYFUNCTION("""COMPUTED_VALUE"""),"ラテ") -> ラテ | K10: =IFERROR(__xludf.DUMMYFUNCTION("""COMPUTED_VALUE"""),"ほとんど飲まない") -> ほとんど飲まない | L10: =IFERROR(__xludf.DUMMYFUNCTION("""COMPUTED_VALUE"""),"抹茶ラテ") -> 抹茶ラテ | N10: =IFERROR(__xludf.DUMMYFUNCTION("""COMPUTED_VALUE"""),"味・風味") -> 味・風味 | P10: =IFERROR(__xludf.DUMMYFUNCTION("""COMPUTED_VALUE"""),"カフェで") -> カフェで | R10: =IFERROR(__xludf.DUMMYFUNCTION("""COMPUTED_VALUE"""),"週に1回") -> 週に1回 | S10: =IFERROR(__xludf.DUMMYFUNCTION("""COMPUTED_VALUE"""),"勉強・仕事をするため") -> 勉強・仕事をするため | U10: =IFERROR(__xludf.DUMMYFUNCTION("""COMPUTED_VALUE"""),"雰囲気・心地良さ") -> 雰囲気・心地良さ | W10: =IFERROR(__xludf.DUMMYFUNCTION("""COMPUTED_VALUE"""),"はい（グローバル）") -> はい（グローバル） | X10: =IFERROR(__xludf.DUMMYFUNCTION("""COMPUTED_VALUE"""),"はい（日本的）") -> はい（日本的） | Y10: =IFERROR(__xludf.DUMMYFUNCTION("""COMPUTED_VALUE"""),4.0) -> 4 | Z10: =IFERROR(__xludf.DUMMYFUNCTION("""COMPUTED_VALUE"""),6.0) -> 6 | AA10: =IFERROR(__xludf.DUMMYFUNCTION("""COMPUTED_VALUE"""),6.0) -> 6 | AB10: =IFERROR(__xludf.DUMMYFUNCTION("""COMPUTED_VALUE"""),"いいえ") -> いいえ | AK10: obLABbe | AL10: QK50l5k | AM10: 46032.254 | AN10: 18-25 | AO10: Female | AP10: Under ¥3,000,000 | AQ10: Chubu | AR10: Daily | AS10: Latte | AU10: Rarely | AV10: Matcha Latte | AX10: =IFERROR(__xludf.DUMMYFUNCTION("""COMPUTED_VALUE"""),"Taste/Flavor") -> Taste/Flavor | AZ10: =IFERROR(__xludf.DUMMYFUNCTION("""COMPUTED_VALUE"""),"At cafés") -> At cafés | BB10: Once a week | BC10: To study/work | BE10: Atmosphere | BG10: Yes, Global | BH10: Yes, Japanese | BI10: 4 | BJ10: 6 | BK10: 6 | BL10: No
A11: =IFERROR(__xludf.DUMMYFUNCTION("""COMPUTED_VALUE"""),"KYKWO6z") -> KYKWO6z | B11: =IFERROR(__xludf.DUMMYFUNCTION("""COMPUTED_VALUE"""),"9qDpb2K") -> 9qDpb2K | C11: =IFERROR(__xludf.DUMMYFUNCTION("""COMPUTED_VALUE"""),46034.05730324074) -> 46034.057 | D11: =IFERROR(__xludf.DUMMYFUNCTION("""COMPUTED_VALUE"""),"18〜25歳") -> 18〜25歳 | E11: =IFERROR(__xludf.DUMMYFUNCTION("""COMPUTED_VALUE"""),"男性") -> 男性 | F11: =IFERROR(__xludf.DUMMYFUNCTION("""COMPUTED_VALUE"""),"300万円〜599万9,999円") -> 300万円〜599万9,999円 | G11: =IFERROR(__xludf.DUMMYFUNCTION("""COMPUTED_VALUE"""),"関東") -> 関東 | H11: =IFERROR(__xludf.DUMMYFUNCTION("""COMPUTED_VALUE"""),"毎日") -> 毎日 | I11: =IFERROR(__xludf.DUMMYFUNCTION("""COMPUTED_VALUE"""),"プアオーバー（ハンドドリップ）") -> プアオーバー（ハンドドリップ） | K11: =IFERROR(__xludf.DUMMYFUNCTION("""COMPUTED_VALUE"""),"ほとんど飲まない") -> ほとんど飲まない | L11: =IFERROR(__xludf.DUMMYFUNCTION("""COMPUTED_VALUE"""),"抹茶ラテ") -> 抹茶ラテ | N11: =IFERROR(__xludf.DUMMYFUNCTION("""COMPUTED_VALUE"""),"その他：") -> その他： | O11: =IFERROR(__xludf.DUMMYFUNCTION("""COMPUTED_VALUE"""),"近さ") -> 近さ | P11: =IFERROR(__xludf.DUMMYFUNCTION("""COMPUTED_VALUE"""),"カフェで, 自宅で") -> カフェで, 自宅で | R11: =IFERROR(__xludf.DUMMYFUNCTION("""COMPUTED_VALUE"""),"週に数回") -> 週に数回 | S11: =IFERROR(__xludf.DUMMYFUNCTION("""COMPUTED_VALUE"""),"習慣として") -> 習慣として | U11: =IFERROR(__xludf.DUMMYFUNCTION("""COMPUTED_VALUE"""),"飲み物の味・品質") -> 飲み物の味・品質 | W11: =IFERROR(__xludf.DUMMYFUNCTION("""COMPUTED_VALUE"""),"はい（グローバル）") -> はい（グローバル） | X11: =IFERROR(__xludf.DUMMYFUNCTION("""COMPUTED_VALUE"""),"はい（日本的）") -> はい（日本的） | Y11: =IFERROR(__xludf.DUMMYFUNCTION("""COMPUTED_VALUE"""),6.0) -> 6 | Z11: =IFERROR(__xludf.DUMMYFUNCTION("""COMPUTED_VALUE"""),6.0) -> 6 | AA11: =IFERROR(__xludf.DUMMYFUNCTION("""COMPUTED_VALUE"""),7.0) -> 7 | AB11: =IFERROR(__xludf.DUMMYFUNCTION("""COMPUTED_VALUE"""),"いいえ") -> いいえ | AK11: KYKWO6z | AL11: 9qDpb2K | AM11: 46034.057 | AN11: 18-25 | AO11: Male | AP11: ¥3,000,000 – ¥5,999,999 | AQ11: Kanto | AR11: Daily | AS11: Pour Over | AU11: Rarely | AV11: Matcha Latte | AX11: =IFERROR(__xludf.DUMMYFUNCTION("""COMPUTED_VALUE"""),"Other:") -> Other: | AY11: Proximity/closeness | AZ11: =IFERROR(__xludf.DUMMYFUNCTION("""COMPUTED_VALUE"""),"At cafés, At home") -> At cafés, At home | BB11: Several times a week | BC11: Out of habit | BE11: Quality of drinks | BG11: Yes, Global | BH11: Yes, Japanese | BI11: 6 | BJ11: 6 | BK11: 7 | BL11: No
A12: =IFERROR(__xludf.DUMMYFUNCTION("""COMPUTED_VALUE"""),"gD6Jpg4") -> gD6Jpg4 | B12: =IFERROR(__xludf.DUMMYFUNCTION("""COMPUTED_VALUE"""),"LZWvQYj") -> LZWvQYj | C12: =IFERROR(__xludf.DUMMYFUNCTION("""COMPUTED_VALUE"""),46034.06355324074) -> 46034.064 | D12: =IFERROR(__xludf.DUMMYFUNCTION("""COMPUTED_VALUE"""),"65歳以上") -> 65歳以上 | E12: =IFERROR(__xludf.DUMMYFUNCTION("""COMPUTED_VALUE"""),"男性") -> 男性 | F12: =IFERROR(__xludf.DUMMYFUNCTION("""COMPUTED_VALUE"""),"300万円〜599万9,999円") -> 300万円〜599万9,999円 | G12: =IFERROR(__xludf.DUMMYFUNCTION("""COMPUTED_VALUE"""),"関東") -> 関東 | H12: =IFERROR(__xludf.DUMMYFUNCTION("""COMPUTED_VALUE"""),"毎日") -> 毎日 | I12: =IFERROR(__xludf.DUMMYFUNCTION("""COMPUTED_VALUE"""),"ドリップコーヒー") -> ドリップコーヒー | K12: =IFERROR(__xludf.DUMMYFUNCTION("""COMPUTED_VALUE"""),"毎日") -> 毎日 | L12: =IFERROR(__xludf.DUMMYFUNCTION("""COMPUTED_VALUE"""),"薄茶") -> 薄茶 | N12: =IFERROR(__xludf.DUMMYFUNCTION("""COMPUTED_VALUE"""),"味・風味, 健康面のメリット") -> 味・風味, 健康面のメリット | P12: =IFERROR(__xludf.DUMMYFUNCTION("""COMPUTED_VALUE"""),"自宅で, 自動販売機") -> 自宅で, 自動販売機 | R12: =IFERROR(__xludf.DUMMYFUNCTION("""COMPUTED_VALUE"""),"月に数回") -> 月に数回 | S12: =IFERROR(__xludf.DUMMYFUNCTION("""COMPUTED_VALUE"""),"習慣として") -> 習慣として | U12: =IFERROR(__xludf.DUMMYFUNCTION("""COMPUTED_VALUE"""),"サービス") -> サービス | W12: =IFERROR(__xludf.DUMMYFUNCTION("""COMPUTED_VALUE"""),"はい（グローバル）") -> はい（グローバル） | X12: =IFERROR(__xludf.DUMMYFUNCTION("""COMPUTED_VALUE"""),"はい（日本的）") -> はい（日本的） | Y12: =IFERROR(__xludf.DUMMYFUNCTION("""COMPUTED_VALUE"""),7.0) -> 7 | Z12: =IFERROR(__xludf.DUMMYFUNCTION("""COMPUTED_VALUE"""),7.0) -> 7 | AA12: =IFERROR(__xludf.DUMMYFUNCTION("""COMPUTED_VALUE"""),4.0) -> 4 | AB12: =IFERROR(__xludf.DUMMYFUNCTION("""COMPUTED_VALUE"""),"いいえ") -> いいえ | AK12: gD6Jpg4 | AL12: LZWvQYj | AM12: 46034.064 | AN12: 65+ | AO12: Male | AP12: ¥3,000,000 – ¥5,999,999 | AQ12: Kanto | AR12: Daily | AS12: Drip | AU12: Daily | AV12: Usucha | AX12: =IFERROR(__xludf.DUMMYFUNCTION("""COMPUTED_VALUE"""),"Taste/Flavor, Health benefits") -> Taste/Flavor, Health benefits | AZ12: =IFERROR(__xludf.DUMMYFUNCTION("""COMPUTED_VALUE"""),"At home, From vending machines") -> At home, From vending machines | BB12: A few times a month | BC12: Out of habit | BE12: Service | BG12: Yes, Global | BH12: Yes, Japanese | BI12: 7 | BJ12: 7 | BK12: 4 | BL12: No
A13: =IFERROR(__xludf.DUMMYFUNCTION("""COMPUTED_VALUE"""),"Ek7ZY0N") -> Ek7ZY0N | B13: =IFERROR(__xludf.DUMMYFUNCTION("""COMPUTED_VALUE"""),"44xAgVY") -> 44xAgVY | C13: =IFERROR(__xludf.DUMMYFUNCTION("""COMPUTED_VALUE"""),46034.06655092593) -> 46034.067 | D13: =IFERROR(__xludf.DUMMYFUNCTION("""COMPUTED_VALUE"""),"56〜65歳") -> 56〜65歳 | E13: =IFERROR(__xludf.DUMMYFUNCTION("""COMPUTED_VALUE"""),"男性") -> 男性 | F13: =IFERROR(__xludf.DUMMYFUNCTION("""COMPUTED_VALUE"""),"1,200万円以上") -> 1,200万円以上 | G13: =IFERROR(__xludf.DUMMYFUNCTION("""COMPUTED_VALUE"""),"関西") -> 関西 | H13: =IFERROR(__xludf.DUMMYFUNCTION("""COMPUTED_VALUE"""),"毎日") -> 毎日 | I13: =IFERROR(__xludf.DUMMYFUNCTION("""COMPUTED_VALUE"""),"ドリップコーヒー") -> ドリップコーヒー | K13: =IFERROR(__xludf.DUMMYFUNCTION("""COMPUTED_VALUE"""),"ほとんど飲まない") -> ほとんど飲まない | L13: =IFERROR(__xludf.DUMMYFUNCTION("""COMPUTED_VALUE"""),"抹茶は飲まない") -> 抹茶は飲まない | N13: =IFERROR(__xludf.DUMMYFUNCTION("""COMPUTED_VALUE"""),"習慣, 味・風味") -> 習慣, 味・風味 | P13: =IFERROR(__xludf.DUMMYFUNCTION("""COMPUTED_VALUE"""),"自宅で, その他：") -> 自宅で, その他： | Q13: =IFERROR(__xludf.DUMMYFUNCTION("""COMPUTED_VALUE"""),"At office") -> At office | R13: =IFERROR(__xludf.DUMMYFUNCTION("""COMPUTED_VALUE"""),"ほとんど行かない") -> ほとんど行かない | S13: =IFERROR(__xludf.DUMMYFUNCTION("""COMPUTED_VALUE"""),"休憩・リラックスするため") -> 休憩・リラックスするため | U13: =IFERROR(__xludf.DUMMYFUNCTION("""COMPUTED_VALUE"""),"雰囲気・心地良さ") -> 雰囲気・心地良さ | W13: =IFERROR(__xludf.DUMMYFUNCTION("""COMPUTED_VALUE"""),"はい（西洋的）") -> はい（西洋的） | X13: =IFERROR(__xludf.DUMMYFUNCTION("""COMPUTED_VALUE"""),"はい（日本的）") -> はい（日本的） | Y13: =IFERROR(__xludf.DUMMYFUNCTION("""COMPUTED_VALUE"""),5.0) -> 5 | Z13: =IFERROR(__xludf.DUMMYFUNCTION("""COMPUTED_VALUE"""),6.0) -> 6 | AA13: =IFERROR(__xludf.DUMMYFUNCTION("""COMPUTED_VALUE"""),1.0) -> 1 | AB13: =IFERROR(__xludf.DUMMYFUNCTION("""COMPUTED_VALUE"""),"いいえ") -> いいえ | AK13: Ek7ZY0N | AL13: 44xAgVY | AM13: 46034.067 | AN13: 56-65 | AO13: Male | AP13: ¥12,000,000 or more | AQ13: Kansai | AR13: Daily | AS13: Drip | AU13: Rarely | AV13: I don’t drink matcha | AX13: =IFERROR(__xludf.DUMMYFUNCTION("""COMPUTED_VALUE"""),"Routine/Ritual, Taste/Flavor") -> Routine/Ritual, Taste/Flavor | AZ13: =IFERROR(__xludf.DUMMYFUNCTION("""COMPUTED_VALUE"""),"At home, Other:") -> At home, Other: | BA13: At office | BB13: Rarely | BC13: To relax or take a break | BE13: Atmosphere | BG13: Yes, Western | BH13: Yes, Japanese | BI13: 5 | BJ13: 6 | BK13: 1 | BL13: No
A14: =IFERROR(__xludf.DUMMYFUNCTION("""COMPUTED_VALUE"""),"gD6JBP1") -> gD6JBP1 | B14: =IFERROR(__xludf.DUMMYFUNCTION("""COMPUTED_VALUE"""),"xXaRM7y") -> xXaRM7y | C14: =IFERROR(__xludf.DUMMYFUNCTION("""COMPUTED_VALUE"""),46034.114224537036) -> 46034.114 | D14: =IFERROR(__xludf.DUMMYFUNCTION("""COMPUTED_VALUE"""),"46〜55歳") -> 46〜55歳 | E14: =IFERROR(__xludf.DUMMYFUNCTION("""COMPUTED_VALUE"""),"女性") -> 女性 | F14: =IFERROR(__xludf.DUMMYFUNCTION("""COMPUTED_VALUE"""),"1,200万円以上") -> 1,200万円以上 | G14: =IFERROR(__xludf.DUMMYFUNCTION("""COMPUTED_VALUE"""),"関東") -> 関東 | H14: =IFERROR(__xludf.DUMMYFUNCTION("""COMPUTED_VALUE"""),"毎日") -> 毎日 | I14: =IFERROR(__xludf.DUMMYFUNCTION("""COMPUTED_VALUE"""),"ドリップコーヒー") -> ドリップコーヒー | K14: =IFERROR(__xludf.DUMMYFUNCTION("""COMPUTED_VALUE"""),"ほとんど飲まない") -> ほとんど飲まない | L14: =IFERROR(__xludf.DUMMYFUNCTION("""COMPUTED_VALUE"""),"薄茶") -> 薄茶 | M14: =IFERROR(__xludf.DUMMYFUNCTION("""COMPUTED_VALUE"""),"煎茶を毎日飲みます") -> 煎茶を毎日飲みます | N14: =IFERROR(__xludf.DUMMYFUNCTION("""COMPUTED_VALUE"""),"エナジー／カフェイン, 味・風味") -> エナジー／カフェイン, 味・風味 | R14: =IFERROR(__xludf.DUMMYFUNCTION("""COMPUTED_VALUE"""),"週に数回") -> 週に数回 | S14: =IFERROR(__xludf.DUMMYFUNCTION("""COMPUTED_VALUE"""),"休憩・リラックスするため") -> 休憩・リラックスするため | U14: =IFERROR(__xludf.DUMMYFUNCTION("""COMPUTED_VALUE"""),"飲み物の味・品質") -> 飲み物の味・品質 | W14: =IFERROR(__xludf.DUMMYFUNCTION("""COMPUTED_VALUE"""),"いいえ") -> いいえ | X14: =IFERROR(__xludf.DUMMYFUNCTION("""COMPUTED_VALUE"""),"はい（日本的）") -> はい（日本的） | Y14: =IFERROR(__xludf.DUMMYFUNCTION("""COMPUTED_VALUE"""),5.0) -> 5 | Z14: =IFERROR(__xludf.DUMMYFUNCTION("""COMPUTED_VALUE"""),7.0) -> 7 | AA14: =IFERROR(__xludf.DUMMYFUNCTION("""COMPUTED_VALUE"""),5.0) -> 5 | AB14: =IFERROR(__xludf.DUMMYFUNCTION("""COMPUTED_VALUE"""),"いいえ") -> いいえ | AK14: gD6JBP1 | AL14: xXaRM7y | AM14: 46034.114 | AN14: 46-55 | AO14: Female | AP14: ¥12,000,000 or more | AQ14: Kanto | AR14: Daily | AS14: Drip | AU14: Rarely | AV14: Usucha | AW14: I drink sencha everyday | AX14: =IFERROR(__xludf.DUMMYFUNCTION("""COMPUTED_VALUE"""),"Energy boost/Caffeine, Taste/Flavor") -> Energy boost/Caffeine, Taste/Flavor | AZ14: =IFERROR(__xludf.DUMMYFUNCTION("""COMPUTED_VALUE"""),"") | BB14: Several times a week | BC14: To relax or take a break | BE14: Quality of drinks | BG14: No | BH14: Yes, Japanese | BI14: 5 | BJ14: 7 | BK14: 5 | BL14: No
A15: =IFERROR(__xludf.DUMMYFUNCTION("""COMPUTED_VALUE"""),"rjMkOgL") -> rjMkOgL | B15: =IFERROR(__xludf.DUMMYFUNCTION("""COMPUTED_VALUE"""),"aQYABpZ") -> aQYABpZ | C15: =IFERROR(__xludf.DUMMYFUNCTION("""COMPUTED_VALUE"""),46034.16165509259) -> 46034.162 | D15: =IFERROR(__xludf.DUMMYFUNCTION("""COMPUTED_VALUE"""),"36〜45歳") -> 36〜45歳 | E15: =IFERROR(__xludf.DUMMYFUNCTION("""COMPUTED_VALUE"""),"女性") -> 女性 | F15: =IFERROR(__xludf.DUMMYFUNCTION("""COMPUTED_VALUE"""),"1,200万円以上") -> 1,200万円以上 | G15: =IFERROR(__xludf.DUMMYFUNCTION("""COMPUTED_VALUE"""),"関東") -> 関東 | H15: =IFERROR(__xludf.DUMMYFUNCTION("""COMPUTED_VALUE"""),"週に1回") -> 週に1回 | I15: =IFERROR(__xludf.DUMMYFUNCTION("""COMPUTED_VALUE"""),"ラテ") -> ラテ | K15: =IFERROR(__xludf.DUMMYFUNCTION("""COMPUTED_VALUE"""),"ほとんど飲まない") -> ほとんど飲まない | L15: =IFERROR(__xludf.DUMMYFUNCTION("""COMPUTED_VALUE"""),"抹茶は飲まない") -> 抹茶は飲まない | N15: =IFERROR(__xludf.DUMMYFUNCTION("""COMPUTED_VALUE"""),"習慣") -> 習慣 | P15: =IFERROR(__xludf.DUMMYFUNCTION("""COMPUTED_VALUE"""),"カフェで") -> カフェで | R15: =IFERROR(__xludf.DUMMYFUNCTION("""COMPUTED_VALUE"""),"週に1回") -> 週に1回 | S15: =IFERROR(__xludf.DUMMYFUNCTION("""COMPUTED_VALUE"""),"休憩・リラックスするため") -> 休憩・リラックスするため | U15: =IFERROR(__xludf.DUMMYFUNCTION("""COMPUTED_VALUE"""),"飲み物の味・品質") -> 飲み物の味・品質 | W15: =IFERROR(__xludf.DUMMYFUNCTION("""COMPUTED_VALUE"""),"はい（西洋的）") -> はい（西洋的） | X15: =IFERROR(__xludf.DUMMYFUNCTION("""COMPUTED_VALUE"""),"はい（日本的）") -> はい（日本的） | Y15: =IFERROR(__xludf.DUMMYFUNCTION("""COMPUTED_VALUE"""),4.0) -> 4 | Z15: =IFERROR(__xludf.DUMMYFUNCTION("""COMPUTED_VALUE"""),7.0) -> 7 | AA15: =IFERROR(__xludf.DUMMYFUNCTION("""COMPUTED_VALUE"""),3.0) -> 3 | AB15: =IFERROR(__xludf.DUMMYFUNCTION("""COMPUTED_VALUE"""),"いいえ") -> いいえ | AK15: rjMkOgL | AL15: aQYABpZ | AM15: 46034.162 | AN15: 36-45 | AO15: Female | AP15: ¥12,000,000 or more | AQ15: Kanto | AR15: Once a week | AS15: Latte | AU15: Rarely | AV15: I don’t drink matcha | AX15: =IFERROR(__xludf.DUMMYFUNCTION("""COMPUTED_VALUE"""),"Routine/Ritual") -> Routine/Ritual | AZ15: =IFERROR(__xludf.DUMMYFUNCTION("""COMPUTED_VALUE"""),"At cafés") -> At cafés | BB15: Once a week | BC15: To relax or take a break | BE15: Quality of drinks | BG15: Yes, Western | BH15: Yes, Japanese | BI15: 4 | BJ15: 7 | BK15: 3 | BL15: No
A16: =IFERROR(__xludf.DUMMYFUNCTION("""COMPUTED_VALUE"""),"0QRD61Q") -> 0QRD61Q | B16: =IFERROR(__xludf.DUMMYFUNCTION("""COMPUTED_VALUE"""),"OD5b0zp") -> OD5b0zp | C16: =IFERROR(__xludf.DUMMYFUNCTION("""COMPUTED_VALUE"""),46034.174108796295) -> 46034.174 | D16: =IFERROR(__xludf.DUMMYFUNCTION("""COMPUTED_VALUE"""),"18〜25歳") -> 18〜25歳 | E16: =IFERROR(__xludf.DUMMYFUNCTION("""COMPUTED_VALUE"""),"女性") -> 女性 | F16: =IFERROR(__xludf.DUMMYFUNCTION("""COMPUTED_VALUE"""),"300万円未満") -> 300万円未満 | G16: =IFERROR(__xludf.DUMMYFUNCTION("""COMPUTED_VALUE"""),"中部") -> 中部 | H16: =IFERROR(__xludf.DUMMYFUNCTION("""COMPUTED_VALUE"""),"毎日") -> 毎日 | I16: =IFERROR(__xludf.DUMMYFUNCTION("""COMPUTED_VALUE"""),"プアオーバー（ハンドドリップ）") -> プアオーバー（ハンドドリップ） | K16: =IFERROR(__xludf.DUMMYFUNCTION("""COMPUTED_VALUE"""),"週に数回") -> 週に数回 | L16: =IFERROR(__xludf.DUMMYFUNCTION("""COMPUTED_VALUE"""),"抹茶ラテ") -> 抹茶ラテ | N16: =IFERROR(__xludf.DUMMYFUNCTION("""COMPUTED_VALUE"""),"その他：, 習慣") -> その他：, 習慣 | R16: =IFERROR(__xludf.DUMMYFUNCTION("""COMPUTED_VALUE"""),"月に数回") -> 月に数回 | S16: =IFERROR(__xludf.DUMMYFUNCTION("""COMPUTED_VALUE"""),"新しい飲み物を試すため") -> 新しい飲み物を試すため | U16: =IFERROR(__xludf.DUMMYFUNCTION("""COMPUTED_VALUE"""),"雰囲気・心地良さ") -> 雰囲気・心地良さ | W16: =IFERROR(__xludf.DUMMYFUNCTION("""COMPUTED_VALUE"""),"はい（グローバル）") -> はい（グローバル） | X16: =IFERROR(__xludf.DUMMYFUNCTION("""COMPUTED_VALUE"""),"はい（日本的）") -> はい（日本的） | Y16: =IFERROR(__xludf.DUMMYFUNCTION("""COMPUTED_VALUE"""),5.0) -> 5 | Z16: =IFERROR(__xludf.DUMMYFUNCTION("""COMPUTED_VALUE"""),4.0) -> 4 | AA16: =IFERROR(__xludf.DUMMYFUNCTION("""COMPUTED_VALUE"""),6.0) -> 6 | AB16: =IFERROR(__xludf.DUMMYFUNCTION("""COMPUTED_VALUE"""),"いいえ") -> いいえ | AK16: 0QRD61Q | AL16: OD5b0zp | AM16: 46034.174 | AN16: 18-25 | AO16: Female | AP16: Under ¥3,000,000 | AQ16: Chubu | AR16: Daily | AS16: Pour Over | AU16: Several times a week | AV16: Matcha Latte | AX16: =IFERROR(__xludf.DUMMYFUNCTION("""COMPUTED_VALUE"""),"Other:, Routine/Ritual") -> Other:, Routine/Ritual | AZ16: =IFERROR(__xludf.DUMMYFUNCTION("""COMPUTED_VALUE"""),"") | BB16: A few times a month | BC16: To try a new drink | BE16: Atmosphere | BG16: Yes, Global | BH16: Yes, Japanese | BI16: 5 | BJ16: 4 | BK16: 6 | BL16: No
A17: =IFERROR(__xludf.DUMMYFUNCTION("""COMPUTED_VALUE"""),"GxAQrlz") -> GxAQrlz | B17: =IFERROR(__xludf.DUMMYFUNCTION("""COMPUTED_VALUE"""),"q4AJOG9") -> q4AJOG9 | C17: =IFERROR(__xludf.DUMMYFUNCTION("""COMPUTED_VALUE"""),46034.18221064815) -> 46034.182 | D17: =IFERROR(__xludf.DUMMYFUNCTION("""COMPUTED_VALUE"""),"26〜35歳") -> 26〜35歳 | E17: =IFERROR(__xludf.DUMMYFUNCTION("""COMPUTED_VALUE"""),"女性") -> 女性 | F17: =IFERROR(__xludf.DUMMYFUNCTION("""COMPUTED_VALUE"""),"300万円未満") -> 300万円未満 | G17: =IFERROR(__xludf.DUMMYFUNCTION("""COMPUTED_VALUE"""),"関西") -> 関西 | H17: =IFERROR(__xludf.DUMMYFUNCTION("""COMPUTED_VALUE"""),"まったく飲まない") -> まったく飲まない | K17: =IFERROR(__xludf.DUMMYFUNCTION("""COMPUTED_VALUE"""),"週に数回") -> 週に数回 | L17: =IFERROR(__xludf.DUMMYFUNCTION("""COMPUTED_VALUE"""),"薄茶") -> 薄茶 | N17: =IFERROR(__xludf.DUMMYFUNCTION("""COMPUTED_VALUE"""),"社交的な場や雰囲気の考慮, 味・風味") -> 社交的な場や雰囲気の考慮, 味・風味 | P17: =IFERROR(__xludf.DUMMYFUNCTION("""COMPUTED_VALUE"""),"その他：") -> その他： | Q17: =IFERROR(__xludf.DUMMYFUNCTION("""COMPUTED_VALUE"""),"仕事") -> 仕事 | R17: =IFERROR(__xludf.DUMMYFUNCTION("""COMPUTED_VALUE"""),"月に数回") -> 月に数回 | S17: =IFERROR(__xludf.DUMMYFUNCTION("""COMPUTED_VALUE"""),"休憩・リラックスするため") -> 休憩・リラックスするため | U17: =IFERROR(__xludf.DUMMYFUNCTION("""COMPUTED_VALUE"""),"雰囲気・心地良さ") -> 雰囲気・心地良さ | W17: =IFERROR(__xludf.DUMMYFUNCTION("""COMPUTED_VALUE"""),"はい（グローバル）") -> はい（グローバル） | X17: =IFERROR(__xludf.DUMMYFUNCTION("""COMPUTED_VALUE"""),"はい（日本的）") -> はい（日本的） | Y17: =IFERROR(__xludf.DUMMYFUNCTION("""COMPUTED_VALUE"""),5.0) -> 5 | Z17: =IFERROR(__xludf.DUMMYFUNCTION("""COMPUTED_VALUE"""),7.0) -> 7 | AA17: =IFERROR(__xludf.DUMMYFUNCTION("""COMPUTED_VALUE"""),7.0) -> 7 | AB17: =IFERROR(__xludf.DUMMYFUNCTION("""COMPUTED_VALUE"""),"いいえ") -> いいえ | AK17: GxAQrlz | AL17: q4AJOG9 | AM17: 46034.182 | AN17: 26-35 | AO17: Female | AP17: Under ¥3,000,000 | AQ17: Kansai | AR17: Never | AU17: Several times a week | AV17: Usucha | AX17: =IFERROR(__xludf.DUMMYFUNCTION("""COMPUTED_VALUE"""),"Social atmosphere, Taste/Flavor") -> Social atmosphere, Taste/Flavor | AZ17: =IFERROR(__xludf.DUMMYFUNCTION("""COMPUTED_VALUE"""),"Other:") -> Other: | BA17: Work | BB17: A few times a month | BC17: To relax or take a break | BE17: Atmosphere | BG17: Yes, Global | BH17: Yes, Japanese | BI17: 5 | BJ17: 7 | BK17: 7 | BL17: No
A18: =IFERROR(__xludf.DUMMYFUNCTION("""COMPUTED_VALUE"""),"Y5lxOQ6") -> Y5lxOQ6 | B18: =IFERROR(__xludf.DUMMYFUNCTION("""COMPUTED_VALUE"""),"Y5WJrKW") -> Y5WJrKW | C18: =IFERROR(__xludf.DUMMYFUNCTION("""COMPUTED_VALUE"""),46034.18680555555) -> 46034.187 | D18: =IFERROR(__xludf.DUMMYFUNCTION("""COMPUTED_VALUE"""),"26〜35歳") -> 26〜35歳 | E18: =IFERROR(__xludf.DUMMYFUNCTION("""COMPUTED_VALUE"""),"男性") -> 男性 | F18: =IFERROR(__xludf.DUMMYFUNCTION("""COMPUTED_VALUE"""),"300万円〜599万9,999円") -> 300万円〜599万9,999円 | G18: =IFERROR(__xludf.DUMMYFUNCTION("""COMPUTED_VALUE"""),"関西") -> 関西 | H18: =IFERROR(__xludf.DUMMYFUNCTION("""COMPUTED_VALUE"""),"週に1回") -> 週に1回 | I18: =IFERROR(__xludf.DUMMYFUNCTION("""COMPUTED_VALUE"""),"ドリップコーヒー") -> ドリップコーヒー | K18: =IFERROR(__xludf.DUMMYFUNCTION("""COMPUTED_VALUE"""),"毎日") -> 毎日 | L18: =IFERROR(__xludf.DUMMYFUNCTION("""COMPUTED_VALUE"""),"薄茶") -> 薄茶 | N18: =IFERROR(__xludf.DUMMYFUNCTION("""COMPUTED_VALUE"""),"習慣, 味・風味") -> 習慣, 味・風味 | P18: =IFERROR(__xludf.DUMMYFUNCTION("""COMPUTED_VALUE"""),"その他：, 自宅で") -> その他：, 自宅で | R18: =IFERROR(__xludf.DUMMYFUNCTION("""COMPUTED_VALUE"""),"週に1回") -> 週に1回 | S18: =IFERROR(__xludf.DUMMYFUNCTION("""COMPUTED_VALUE"""),"休憩・リラックスするため") -> 休憩・リラックスするため | U18: =IFERROR(__xludf.DUMMYFUNCTION("""COMPUTED_VALUE"""),"サービス") -> サービス | W18: =IFERROR(__xludf.DUMMYFUNCTION("""COMPUTED_VALUE"""),"はい（グローバル）") -> はい（グローバル） | X18: =IFERROR(__xludf.DUMMYFUNCTION("""COMPUTED_VALUE"""),"はい（グローバル）") -> はい（グローバル） | Y18: =IFERROR(__xludf.DUMMYFUNCTION("""COMPUTED_VALUE"""),7.0) -> 7 | Z18: =IFERROR(__xludf.DUMMYFUNCTION("""COMPUTED_VALUE"""),7.0) -> 7 | AA18: =IFERROR(__xludf.DUMMYFUNCTION("""COMPUTED_VALUE"""),5.0) -> 5 | AB18: =IFERROR(__xludf.DUMMYFUNCTION("""COMPUTED_VALUE"""),"はい") -> はい | AK18: Y5lxOQ6 | AL18: Y5WJrKW | AM18: 46034.187 | AN18: 26-35 | AO18: Male | AP18: ¥3,000,000 – ¥5,999,999 | AQ18: Kansai | AR18: Once a week | AS18: Drip | AU18: Daily | AV18: Usucha | AX18: =IFERROR(__xludf.DUMMYFUNCTION("""COMPUTED_VALUE"""),"Routine/Ritual, Taste/Flavor") -> Routine/Ritual, Taste/Flavor | AZ18: =IFERROR(__xludf.DUMMYFUNCTION("""COMPUTED_VALUE"""),"Other:, At home") -> Other:, At home | BB18: Once a week | BC18: To relax or take a break | BE18: Service | BG18: Yes, Global | BH18: Yes, Global | BI18: 7 | BJ18: 7 | BK18: 5 | BL18: Yes
A19: =IFERROR(__xludf.DUMMYFUNCTION("""COMPUTED_VALUE"""),"Ek7NOBr") -> Ek7NOBr | B19: =IFERROR(__xludf.DUMMYFUNCTION("""COMPUTED_VALUE"""),"J9AeG1K") -> J9AeG1K | C19: =IFERROR(__xludf.DUMMYFUNCTION("""COMPUTED_VALUE"""),46034.28605324074) -> 46034.286 | D19: =IFERROR(__xludf.DUMMYFUNCTION("""COMPUTED_VALUE"""),"26〜35歳") -> 26〜35歳 | E19: =IFERROR(__xludf.DUMMYFUNCTION("""COMPUTED_VALUE"""),"男性") -> 男性 | F19: =IFERROR(__xludf.DUMMYFUNCTION("""COMPUTED_VALUE"""),"300万円〜599万9,999円") -> 300万円〜599万9,999円 | G19: =IFERROR(__xludf.DUMMYFUNCTION("""COMPUTED_VALUE"""),"九州") -> 九州 | H19: =IFERROR(__xludf.DUMMYFUNCTION("""COMPUTED_VALUE"""),"毎日") -> 毎日 | I19: =IFERROR(__xludf.DUMMYFUNCTION("""COMPUTED_VALUE"""),"ドリップコーヒー") -> ドリップコーヒー | K19: =IFERROR(__xludf.DUMMYFUNCTION("""COMPUTED_VALUE"""),"ほとんど飲まない") -> ほとんど飲まない | L19: =IFERROR(__xludf.DUMMYFUNCTION("""COMPUTED_VALUE"""),"濃茶") -> 濃茶 | N19: =IFERROR(__xludf.DUMMYFUNCTION("""COMPUTED_VALUE"""),"味・風味") -> 味・風味 | P19: =IFERROR(__xludf.DUMMYFUNCTION("""COMPUTED_VALUE"""),"自宅で, カフェで, コンビニ（セブンイレブン、ローソンなど）, 自動販売機") -> 自宅で, カフェで, コンビニ（セブンイレブン、ローソンなど）, 自動販売機 | R19: =IFERROR(__xludf.DUMMYFUNCTION("""COMPUTED_VALUE"""),"月に数回") -> 月に数回 | S19: =IFERROR(__xludf.DUMMYFUNCTION("""COMPUTED_VALUE"""),"休憩・リラックスするため") -> 休憩・リラックスするため | U19: =IFERROR(__xludf.DUMMYFUNCTION("""COMPUTED_VALUE"""),"飲み物の味・品質") -> 飲み物の味・品質 | W19: =IFERROR(__xludf.DUMMYFUNCTION("""COMPUTED_VALUE"""),"はい（グローバル）") -> はい（グローバル） | X19: =IFERROR(__xludf.DUMMYFUNCTION("""COMPUTED_VALUE"""),"はい（日本的）") -> はい（日本的） | Y19: =IFERROR(__xludf.DUMMYFUNCTION("""COMPUTED_VALUE"""),7.0) -> 7 | Z19: =IFERROR(__xludf.DUMMYFUNCTION("""COMPUTED_VALUE"""),7.0) -> 7 | AA19: =IFERROR(__xludf.DUMMYFUNCTION("""COMPUTED_VALUE"""),7.0) -> 7 | AB19: =IFERROR(__xludf.DUMMYFUNCTION("""COMPUTED_VALUE"""),"はい") -> はい | AK19: Ek7NOBr | AL19: J9AeG1K | AM19: 46034.286 | AN19: 26-35 | AO19: Male | AP19: ¥3,000,000 – ¥5,999,999 | AQ19: Kyushu | AR19: Daily | AS19: Drip | AU19: Rarely | AV19: Koicha | AX19: =IFERROR(__xludf.DUMMYFUNCTION("""COMPUTED_VALUE"""),"Taste/Flavor") -> Taste/Flavor | AZ19: =IFERROR(__xludf.DUMMYFUNCTION("""COMPUTED_VALUE"""),"At home, At cafés, From convenience stores (7-Eleven, Lawson, etc.), From vending machines") -> At home, At cafés, From convenience stores (7-Eleven, Lawson, etc.), From vending machines | BB19: A few times a month | BC19: To relax or take a break | BE19: Quality of drinks | BG19: Yes, Global | BH19: Yes, Japanese | BI19: 7 | BJ19: 7 | BK19: 7 | BL19: Yes
A20: =IFERROR(__xludf.DUMMYFUNCTION("""COMPUTED_VALUE"""),"eqWY140") -> eqWY140 | B20: =IFERROR(__xludf.DUMMYFUNCTION("""COMPUTED_VALUE"""),"vGyJ12X") -> vGyJ12X | C20: =IFERROR(__xludf.DUMMYFUNCTION("""COMPUTED_VALUE"""),46034.31005787037) -> 46034.31 | D20: =IFERROR(__xludf.DUMMYFUNCTION("""COMPUTED_VALUE"""),"65歳以上") -> 65歳以上 | E20: =IFERROR(__xludf.DUMMYFUNCTION("""COMPUTED_VALUE"""),"男性") -> 男性 | F20: =IFERROR(__xludf.DUMMYFUNCTION("""COMPUTED_VALUE"""),"1,200万円以上") -> 1,200万円以上 | G20: =IFERROR(__xludf.DUMMYFUNCTION("""COMPUTED_VALUE"""),"関東") -> 関東 | H20: =IFERROR(__xludf.DUMMYFUNCTION("""COMPUTED_VALUE"""),"週に1回") -> 週に1回 | I20: =IFERROR(__xludf.DUMMYFUNCTION("""COMPUTED_VALUE"""),"フレーバーコーヒー（モカ、バニラ、キャラメルなど）") -> フレーバーコーヒー（モカ、バニラ、キャラメルなど） | K20: =IFERROR(__xludf.DUMMYFUNCTION("""COMPUTED_VALUE"""),"週に1回") -> 週に1回 | L20: =IFERROR(__xludf.DUMMYFUNCTION("""COMPUTED_VALUE"""),"濃茶") -> 濃茶 | N20: =IFERROR(__xludf.DUMMYFUNCTION("""COMPUTED_VALUE"""),"健康面のメリット") -> 健康面のメリット | P20: =IFERROR(__xludf.DUMMYFUNCTION("""COMPUTED_VALUE"""),"自宅で") -> 自宅で | R20: =IFERROR(__xludf.DUMMYFUNCTION("""COMPUTED_VALUE"""),"ほとんど行かない") -> ほとんど行かない | S20: =IFERROR(__xludf.DUMMYFUNCTION("""COMPUTED_VALUE"""),"休憩・リラックスするため") -> 休憩・リラックスするため | U20: =IFERROR(__xludf.DUMMYFUNCTION("""COMPUTED_VALUE"""),"雰囲気・心地良さ") -> 雰囲気・心地良さ | W20: =IFERROR(__xludf.DUMMYFUNCTION("""COMPUTED_VALUE"""),"いいえ") -> いいえ | X20: =IFERROR(__xludf.DUMMYFUNCTION("""COMPUTED_VALUE"""),"はい（日本的）") -> はい（日本的） | Y20: =IFERROR(__xludf.DUMMYFUNCTION("""COMPUTED_VALUE"""),6.0) -> 6 | Z20: =IFERROR(__xludf.DUMMYFUNCTION("""COMPUTED_VALUE"""),7.0) -> 7 | AA20: =IFERROR(__xludf.DUMMYFUNCTION("""COMPUTED_VALUE"""),4.0) -> 4 | AB20: =IFERROR(__xludf.DUMMYFUNCTION("""COMPUTED_VALUE"""),"いいえ") -> いいえ | AK20: eqWY140 | AL20: vGyJ12X | AM20: 46034.31 | AN20: 65+ | AO20: Male | AP20: ¥12,000,000 or more | AQ20: Kanto | AR20: Once a week | AS20: Flavored coffee (mocha, vanilla, caramel, etc.) | AU20: Once a week | AV20: Koicha | AX20: =IFERROR(__xludf.DUMMYFUNCTION("""COMPUTED_VALUE"""),"Health benefits") -> Health benefits | AZ20: =IFERROR(__xludf.DUMMYFUNCTION("""COMPUTED_VALUE"""),"At home") -> At home | BB20: Rarely | BC20: To relax or take a break | BE20: Atmosphere | BG20: No | BH20: Yes, Japanese | BI20: 6 | BJ20: 7 | BK20: 4 | BL20: No
A21: =IFERROR(__xludf.DUMMYFUNCTION("""COMPUTED_VALUE"""),"lbkvb1W") -> lbkvb1W | B21: =IFERROR(__xludf.DUMMYFUNCTION("""COMPUTED_VALUE"""),"EkQZE4l") -> EkQZE4l | C21: =IFERROR(__xludf.DUMMYFUNCTION("""COMPUTED_VALUE"""),46034.315) -> 46034.315 | D21: =IFERROR(__xludf.DUMMYFUNCTION("""COMPUTED_VALUE"""),"26〜35歳") -> 26〜35歳 | E21: =IFERROR(__xludf.DUMMYFUNCTION("""COMPUTED_VALUE"""),"女性") -> 女性 | F21: =IFERROR(__xludf.DUMMYFUNCTION("""COMPUTED_VALUE"""),"600万円〜899万9,999円") -> 600万円〜899万9,999円 | G21: =IFERROR(__xludf.DUMMYFUNCTION("""COMPUTED_VALUE"""),"関東") -> 関東 | H21: =IFERROR(__xludf.DUMMYFUNCTION("""COMPUTED_VALUE"""),"毎日") -> 毎日 | I21: =IFERROR(__xludf.DUMMYFUNCTION("""COMPUTED_VALUE"""),"ドリップコーヒー") -> ドリップコーヒー | K21: =IFERROR(__xludf.DUMMYFUNCTION("""COMPUTED_VALUE"""),"ほとんど飲まない") -> ほとんど飲まない | L21: =IFERROR(__xludf.DUMMYFUNCTION("""COMPUTED_VALUE"""),"抹茶ラテ") -> 抹茶ラテ | N21: =IFERROR(__xludf.DUMMYFUNCTION("""COMPUTED_VALUE"""),"習慣, 味・風味") -> 習慣, 味・風味 | P21: =IFERROR(__xludf.DUMMYFUNCTION("""COMPUTED_VALUE"""),"自宅で, コンビニ（セブンイレブン、ローソンなど）") -> 自宅で, コンビニ（セブンイレブン、ローソンなど） | R21: =IFERROR(__xludf.DUMMYFUNCTION("""COMPUTED_VALUE"""),"月に数回") -> 月に数回 | S21: =IFERROR(__xludf.DUMMYFUNCTION("""COMPUTED_VALUE"""),"友人と会うため") -> 友人と会うため | U21: =IFERROR(__xludf.DUMMYFUNCTION("""COMPUTED_VALUE"""),"雰囲気・心地良さ") -> 雰囲気・心地良さ | W21: =IFERROR(__xludf.DUMMYFUNCTION("""COMPUTED_VALUE"""),"いいえ") -> いいえ | X21: =IFERROR(__xludf.DUMMYFUNCTION("""COMPUTED_VALUE"""),"いいえ") -> いいえ | Y21: =IFERROR(__xludf.DUMMYFUNCTION("""COMPUTED_VALUE"""),7.0) -> 7 | Z21: =IFERROR(__xludf.DUMMYFUNCTION("""COMPUTED_VALUE"""),4.0) -> 4 | AA21: =IFERROR(__xludf.DUMMYFUNCTION("""COMPUTED_VALUE"""),4.0) -> 4 | AB21: =IFERROR(__xludf.DUMMYFUNCTION("""COMPUTED_VALUE"""),"いいえ") -> いいえ | AK21: lbkvb1W | AL21: EkQZE4l | AM21: 46034.315 | AN21: 26-35 | AO21: Female | AP21: ¥6,000,000 – ¥8,999,999 | AQ21: Kanto | AR21: Daily | AS21: Drip | AU21: Rarely | AV21: Matcha Latte | AX21: =IFERROR(__xludf.DUMMYFUNCTION("""COMPUTED_VALUE"""),"Routine/Ritual, Taste/Flavor") -> Routine/Ritual, Taste/Flavor | AZ21: =IFERROR(__xludf.DUMMYFUNCTION("""COMPUTED_VALUE"""),"At home, From convenience stores (7-Eleven, Lawson, etc.)") -> At home, From convenience stores (7-Eleven, Lawson, etc.) | BB21: A few times a month | BC21: To meet friends | BE21: Atmosphere | BG21: No | BH21: No | BI21: 7 | BJ21: 4 | BK21: 4 | BL21: No
A22: =IFERROR(__xludf.DUMMYFUNCTION("""COMPUTED_VALUE"""),"68EP7gY") -> 68EP7gY | B22: =IFERROR(__xludf.DUMMYFUNCTION("""COMPUTED_VALUE"""),"2ENDrBg") -> 2ENDrBg | C22: =IFERROR(__xludf.DUMMYFUNCTION("""COMPUTED_VALUE"""),46034.46233796296) -> 46034.462 | D22: =IFERROR(__xludf.DUMMYFUNCTION("""COMPUTED_VALUE"""),"56〜65歳") -> 56〜65歳 | E22: =IFERROR(__xludf.DUMMYFUNCTION("""COMPUTED_VALUE"""),"男性") -> 男性 | F22: =IFERROR(__xludf.DUMMYFUNCTION("""COMPUTED_VALUE"""),"600万円〜899万9,999円") -> 600万円〜899万9,999円 | G22: =IFERROR(__xludf.DUMMYFUNCTION("""COMPUTED_VALUE"""),"関東") -> 関東 | H22: =IFERROR(__xludf.DUMMYFUNCTION("""COMPUTED_VALUE"""),"毎日") -> 毎日 | I22: =IFERROR(__xludf.DUMMYFUNCTION("""COMPUTED_VALUE"""),"ドリップコーヒー") -> ドリップコーヒー | K22: =IFERROR(__xludf.DUMMYFUNCTION("""COMPUTED_VALUE"""),"ほとんど飲まない") -> ほとんど飲まない | L22: =IFERROR(__xludf.DUMMYFUNCTION("""COMPUTED_VALUE"""),"抹茶ラテ") -> 抹茶ラテ | N22: =IFERROR(__xludf.DUMMYFUNCTION("""COMPUTED_VALUE"""),"味・風味, 社会的トレンドに同調・周囲の影響（周りの人がよく飲んでいるもの）") -> 味・風味, 社会的トレンドに同調・周囲の影響（周りの人がよく飲んでいるもの） | P22: =IFERROR(__xludf.DUMMYFUNCTION("""COMPUTED_VALUE"""),"コンビニ（セブンイレブン、ローソンなど）, その他：") -> コンビニ（セブンイレブン、ローソンなど）, その他： | Q22: =IFERROR(__xludf.DUMMYFUNCTION("""COMPUTED_VALUE"""),"オフィス") -> オフィス | R22: =IFERROR(__xludf.DUMMYFUNCTION("""COMPUTED_VALUE"""),"月に数回") -> 月に数回 | S22: =IFERROR(__xludf.DUMMYFUNCTION("""COMPUTED_VALUE"""),"勉強・仕事をするため") -> 勉強・仕事をするため | U22: =IFERROR(__xludf.DUMMYFUNCTION("""COMPUTED_VALUE"""),"雰囲気・心地良さ") -> 雰囲気・心地良さ | W22: =IFERROR(__xludf.DUMMYFUNCTION("""COMPUTED_VALUE"""),"はい（西洋的）") -> はい（西洋的） | X22: =IFERROR(__xludf.DUMMYFUNCTION("""COMPUTED_VALUE"""),"はい（日本的）") -> はい（日本的） | Y22: =IFERROR(__xludf.DUMMYFUNCTION("""COMPUTED_VALUE"""),7.0) -> 7 | Z22: =IFERROR(__xludf.DUMMYFUNCTION("""COMPUTED_VALUE"""),7.0) -> 7 | AA22: =IFERROR(__xludf.DUMMYFUNCTION("""COMPUTED_VALUE"""),2.0) -> 2 | AB22: =IFERROR(__xludf.DUMMYFUNCTION("""COMPUTED_VALUE"""),"いいえ") -> いいえ | AK22: 68EP7gY | AL22: 2ENDrBg | AM22: 46034.462 | AN22: 56-65 | AO22: Male | AP22: ¥6,000,000 – ¥8,999,999 | AQ22: Kanto | AR22: Daily | AS22: Drip | AU22: Rarely | AV22: Matcha Latte | AX22: =IFERROR(__xludf.DUMMYFUNCTION("""COMPUTED_VALUE"""),"Taste/Flavor, Social norms / influence (what people around me usually drink)") -> Taste/Flavor, Social norms / influence (what people around me usually drink) | AZ22: =IFERROR(__xludf.DUMMYFUNCTION("""COMPUTED_VALUE"""),"From convenience stores (7-Eleven, Lawson, etc.), Other:") -> From convenience stores (7-Eleven, Lawson, etc.), Other: | BA22: Office | BB22: A few times a month | BC22: To study/work | BE22: Atmosphere | BG22: Yes, Western | BH22: Yes, Japanese | BI22: 7 | BJ22: 7 | BK22: 2 | BL22: No
A23: =IFERROR(__xludf.DUMMYFUNCTION("""COMPUTED_VALUE"""),"9qjreME") -> 9qjreME | B23: =IFERROR(__xludf.DUMMYFUNCTION("""COMPUTED_VALUE"""),"2EN7klD") -> 2EN7klD | C23: =IFERROR(__xludf.DUMMYFUNCTION("""COMPUTED_VALUE"""),46034.64092592592) -> 46034.641 | D23: =IFERROR(__xludf.DUMMYFUNCTION("""COMPUTED_VALUE"""),"46〜55歳") -> 46〜55歳 | E23: =IFERROR(__xludf.DUMMYFUNCTION("""COMPUTED_VALUE"""),"男性") -> 男性 | F23: =IFERROR(__xludf.DUMMYFUNCTION("""COMPUTED_VALUE"""),"900万円〜1,199万9,999円") -> 900万円〜1,199万9,999円 | G23: =IFERROR(__xludf.DUMMYFUNCTION("""COMPUTED_VALUE"""),"関東") -> 関東 | H23: =IFERROR(__xludf.DUMMYFUNCTION("""COMPUTED_VALUE"""),"毎日") -> 毎日 | I23: =IFERROR(__xludf.DUMMYFUNCTION("""COMPUTED_VALUE"""),"ドリップコーヒー") -> ドリップコーヒー | K23: =IFERROR(__xludf.DUMMYFUNCTION("""COMPUTED_VALUE"""),"ほとんど飲まない") -> ほとんど飲まない | L23: =IFERROR(__xludf.DUMMYFUNCTION("""COMPUTED_VALUE"""),"抹茶ラテ") -> 抹茶ラテ | N23: =IFERROR(__xludf.DUMMYFUNCTION("""COMPUTED_VALUE"""),"味・風味, 価格") -> 味・風味, 価格 | P23: =IFERROR(__xludf.DUMMYFUNCTION("""COMPUTED_VALUE"""),"カフェで, 自宅で, コンビニ（セブンイレブン、ローソンなど）, 自動販売機") -> カフェで, 自宅で, コンビニ（セブンイレブン、ローソンなど）, 自動販売機 | R23: =IFERROR(__xludf.DUMMYFUNCTION("""COMPUTED_VALUE"""),"月に数回") -> 月に数回 | S23: =IFERROR(__xludf.DUMMYFUNCTION("""COMPUTED_VALUE"""),"勉強・仕事をするため") -> 勉強・仕事をするため | U23: =IFERROR(__xludf.DUMMYFUNCTION("""COMPUTED_VALUE"""),"雰囲気・心地良さ") -> 雰囲気・心地良さ | W23: =IFERROR(__xludf.DUMMYFUNCTION("""COMPUTED_VALUE"""),"はい（グローバル）") -> はい（グローバル） | X23: =IFERROR(__xludf.DUMMYFUNCTION("""COMPUTED_VALUE"""),"はい（日本的）") -> はい（日本的） | Y23: =IFERROR(__xludf.DUMMYFUNCTION("""COMPUTED_VALUE"""),7.0) -> 7 | Z23: =IFERROR(__xludf.DUMMYFUNCTION("""COMPUTED_VALUE"""),7.0) -> 7 | AA23: =IFERROR(__xludf.DUMMYFUNCTION("""COMPUTED_VALUE"""),4.0) -> 4 | AB23: =IFERROR(__xludf.DUMMYFUNCTION("""COMPUTED_VALUE"""),"いいえ") -> いいえ | AK23: 9qjreME | AL23: 2EN7klD | AM23: 46034.641 | AN23: 46-55 | AO23: Male | AP23: ¥9,000,000 – ¥11,999,999 | AQ23: Kanto | AR23: Daily | AS23: Drip | AU23: Rarely | AV23: Matcha Latte | AX23: =IFERROR(__xludf.DUMMYFUNCTION("""COMPUTED_VALUE"""),"Taste/Flavor, Price") -> Taste/Flavor, Price | AZ23: =IFERROR(__xludf.DUMMYFUNCTION("""COMPUTED_VALUE"""),"At cafés, At home, From convenience stores (7-Eleven, Lawson, etc.), From vending machines") -> At cafés, At home, From convenience stores (7-Eleven, Lawson, etc.), From vending machines | BB23: A few times a month | BC23: To study/work | BE23: Atmosphere | BG23: Yes, Global | BH23: Yes, Japanese | BI23: 7 | BJ23: 7 | BK23: 4 | BL23: No
